Traceback (most recent call last):
  File "/base/python_lib/versions/1/google/appengine/ext/webapp/__init__.py", line 499, in __call__
    handler.get(*groups)
  File "/base/data/home/apps/g02me/6.1/shell.py", line 297, in get
    session.put()
  File "/base/python_lib/versions/1/google/appengine/ext/db/__init__.py", line 618, in put
    return datastore.Put(self._entity)
  File "/base/python_lib/versions/1/google/appengine/api/datastore.py", line 162, in Put
    raise _ToDatastoreError(err)
  File "/base/python_lib/versions/1/google/appengine/api/datastore.py", line 1627, in _ToDatastoreError
    raise errors[err.application_error](err.error_detail)
Timeout
>>> 
Traceback (most recent call last):
  File "/base/python_lib/versions/1/google/appengine/ext/webapp/__init__.py", line 499, in __call__
    handler.get(*groups)
  File "/base/data/home/apps/g02me/6.1/shell.py", line 297, in get
    session.put()
  File "/base/python_lib/versions/1/google/appengine/ext/db/__init__.py", line 618, in put
    return datastore.Put(self._entity)
  File "/base/python_lib/versions/1/google/appengine/api/datastore.py", line 162, in Put
    raise _ToDatastoreError(err)
  File "/base/python_lib/versions/1/google/appengine/api/datastore.py", line 1627, in _ToDatastoreError
    raise errors[err.application_error](err.error_detail)
Timeout

http://www.imdb.com/name/nm2395586/
Christopher Mintz-Plasse
userAuthFirst: 24.16.108.51
2008-11-09 16:55:57.638626
shareCount: 0
sTags: : (dp0 . 

5P looks like a fake URL...titled redit
